<?xml version="1.0" ?>

<mujoco>
  <compiler angle="radian" coordinate="local" meshdir="meshes/"/>
  <default> 
    <joint damping="0.5"/>   
    <default class="visual">
      <geom contype="0" conaffinity="0"/>
    </default>
  </default>  
  <asset>
    <mesh name="link_0_mesh" file="link_0.stl"/>
    <mesh name="link_1_mesh" file="link_1.stl"/>
    <mesh name="link_2_mesh" file="link_2.stl"/>
    <mesh name="link_3_mesh" file="link_3.stl"/>
    <mesh name="link_4_mesh" file="link_4.stl"/>
    <mesh name="link_5_mesh" file="link_5.stl"/>
    <mesh name="link_6_mesh" file="link_6.stl"/>
    <mesh name="link_7_mesh" file="link_7.stl"/>
    <material name="orange" rgba="1.0 0.423529411765 0.0392156862745 1.0"/>
    <material name="grey" rgba="0.4 0.4 0.4 1.0"/>
  </asset>
  <worldbody>
    <geom class="visual" type="plane" size="10 10 1"/>
    <body name="link_0">
      <geom class="visual" type="mesh" mesh="link_0_mesh" material="grey"/>
      <body name="link_1" pos="0 0 0.1575">
        <joint name="joint_1" axis="0 0 1" limited="true" range="-2.96705972839 2.96705972839"/>
        <inertial euler="0 0 0" pos="0 -0.03 0.12" mass="5.76" diaginertia="0.033 0.0333 0.0123"/>
        <geom class="visual" type="mesh" mesh="link_1_mesh" material="grey"/>
        <body name="link_2" euler="1.570796326794897 3.141592653589793 0" pos="0 0 0.2025">
          <joint name="joint_2" axis="0 0 1" limited="true" range="-2.09439510239 2.09439510239"/>
          <inertial euler="0 0 0" pos="0.0003 0.059 0.042" mass="6.35" diaginertia="0.0305 0.0304 0.011"/>
          <geom class="visual" type="mesh" mesh="link_2_mesh" material="orange"/>
          <body name="link_3" euler="1.570796326794897 3.141592653589793 0" pos="0 0.2045 0">
            <joint name="joint_3" axis="0 0 1" limited="true" range="-2.96705972839 2.96705972839"/>
            <inertial euler="0 0 0" pos="0 0.03 0.13" mass="3.5" diaginertia="0.025 0.0238 0.0076"/>
            <geom class="visual" type="mesh" mesh="link_3_mesh" material="grey"/>
            <body name="link_4" euler="1.570796326794897 0 0" pos="0 0 0.2155">
              <joint name="joint_4" axis="0 0 1" limited="true" range="-2.09439510239 2.09439510239"/>
              <inertial euler="0 0 0" pos="0 0.067 0.034" mass="3.5" diaginertia="0.017 0.0164 0.006"/>
              <geom class="visual" type="mesh" mesh="link_4_mesh" material="orange"/>
              <body name="link_5" euler="-1.570796326794897 0 3.141592653589793" pos="0 0.1845 0">
                <joint name="joint_5" axis="0 0 1" limited="true" range="-2.96705972839 2.96705972839"/>
                <inertial euler="0 0 0" pos="0.0001 0.021 0.076" mass="3.5" diaginertia="0.01 0.0087 0.00449"/>
                <geom class="visual" type="mesh" mesh="link_5_mesh" material="grey"/>
                <body name="link_6" euler="1.570796326794897 0 0" pos="0 0 0.2155">
                  <joint name="joint_6" axis="0 0 1" limited="true" range="-2.09439510239 2.09439510239"/>
                  <inertial euler="0 0 0" pos="0 0.0006 0.0004" mass="1.8" diaginertia="0.0049 0.0047 0.0036"/>
                  <geom class="visual" type="mesh" mesh="link_6_mesh" material="orange"/>
                  <body name="link_7" euler="-1.570796326794897 3.141592653589793 0" pos="0 0.081 0">
                    <joint name="joint_7" axis="0 0 1" limited="true" range="-3.05432619099 3.05432619099"/>
                    <inertial euler="0 0 0" pos="0 0 0.02" mass="1.2" diaginertia="0.001 0.001 0.001"/> <!-- TODO -->
                    <geom class="visual" type="mesh" mesh="link_7_mesh" material="grey"/>
                  </body>
                </body>
              </body>
            </body>
          </body>
        </body>
      </body>
    </body>
  </worldbody>
  <actuator>
    <motor ctrllimited="true" ctrlrange="-1.0 1.0" gear="300.0" joint="joint_1"/>
    <motor ctrllimited="true" ctrlrange="-1.0 1.0" gear="300.0" joint="joint_2"/>
    <motor ctrllimited="true" ctrlrange="-1.0 1.0" gear="300.0" joint="joint_3"/>
    <motor ctrllimited="true" ctrlrange="-1.0 1.0" gear="300.0" joint="joint_4"/>
    <motor ctrllimited="true" ctrlrange="-1.0 1.0" gear="300.0" joint="joint_5"/>
    <motor ctrllimited="true" ctrlrange="-1.0 1.0" gear="300.0" joint="joint_6"/>
    <motor ctrllimited="true" ctrlrange="-1.0 1.0" gear="300.0" joint="joint_7"/>
  </actuator>
</mujoco>